Workbook

Sheet Tong quan
A1: Bảng tổng hợp đánh giá VAD – YAMNet, bin 0.5s
A2: Pipeline: file mp3/mp4 → decode (app) → PCM → lib: resample, downmix → cửa sổ 0.96 s / hop 0.08 s → model → gộp overlap → padding, drop, merge → segment. Xử lý theo file, không streaming.
A4: Cách dùng
A5: Ô nền vàng | B5: Ô bạn điền (trạng thái, kết quả đo, số liệu).
A6: Ô nền xám | B6: Số liệu ví dụ minh họa — ghi đè bằng kết quả thật.
A7: Ô chữ đen không nền | B7: Công thức tự tính, không cần sửa.
A8: Các sheet
A9: Ke hoach baseline | B9: Kế hoạch và theo dõi từng bước xây baseline: phụ trách, hạn, trạng thái, bằng chứng; tiến độ theo nhóm.
A10: KPI va Gate | B10: KPI của lib, baseline vs candidate: target, dung sai, CI Δ, kết luận đạt / không đạt.
A11: Snapshot | B11: Cấu hình được đóng băng (input lib, tiền xử lý, gộp overlap, hậu xử lý…); tự đánh dấu mục thay đổi.
A12: Quy trinh 8 buoc | B12: 8 bước đánh giá, đầu ra và công cụ; theo dõi tiến độ.
A13: Metrics | B13: Định nghĩa metric tầng A, B, C (hiệu năng lib), S (biên, file, parity), I (tích hợp decode).
A14: Kiem tra du lieu | B14: Checklist 18 mục kiểm tra chất lượng dữ liệu (Bước 8).
A15: Ablation | B15: Hậu xử lý A0–A4, cách gộp overlap, drop, thứ tự hậu xử lý; DCF tự tính.
A16: Bao cao category | B16: Mẫu báo cáo theo category: MR, FAR, loại lỗi, F1, DCF. Baseline chính thức điền bằng output của lib.
A17: Bieu do can ve | B17: Danh sách biểu đồ nên có.
A18: Parity | B18: So khớp Python reference ↔ lib theo thứ tự pipeline: waveform, log-mel, score, overlap, quyết định, segment.
A19: Performance | B19: Thời gian theo stage (ms / phút audio), RTF, CPU, năng lượng, bộ nhớ cố định, kích thước.
A20: Bien va timestamp | B20: Độ chính xác biên trên nhãn mịn, chất lượng theo vị trí trong file, căn chỉnh thời gian.
... A25: Tich hop decode | B25: Decode mp3/mp4 phía app (ngoài lib): lệch timestamp, định dạng, file lỗi. Không tính vào gate của lib.
A26: Tiến độ
A27: Tiến độ quy trình | B27: ='Quy trinh 8 buoc'!B14
A28: Checklist dữ liệu đã xong | B28: ='Kiem tra du lieu'!C30
A29: Số mục dữ liệu 'Không đạt' | B29: ='Kiem tra du lieu'!C26
A30: Tiến độ kế hoạch baseline | B30: ='Ke hoach baseline'!I50
A31: Số bước đang trễ hạn | B31: ='Ke hoach baseline'!D51
A32: KPI: Đạt / Không đạt / Chưa đo | B32: ='KPI va Gate'!D32&" / "&'KPI va Gate'!D33&" / "&'KPI va Gate'!D34
A33: Kết luận gate của lib | B33: ='KPI va Gate'!D36
A34: Parity lib baseline: không đạt / chưa đo | B34: =Parity!F25&" / "&Parity!F26
A35: Test chức năng baseline: không đạt / chưa chạy | B35: ='Test chuc nang'!F38&" / "&'Test chuc nang'!F39
A36: Tích hợp decode: không đạt / chưa chạy | B36: ='Tich hop decode'!C46+'Tich hop decode'!D46&" / "&'Tich hop decode'!C47+'Tich hop decode'!D47
A37: Lưu ý chính
A38: 1 | B38: AUC gộp trên dữ liệu thiết kế dễ bị thổi phồng — kiểm tra rò rỉ, file suy biến, alignment trước.
A39: 2 | B39: Chọn ngưỡng trên dev qua toàn pipeline, không chọn trên test.
A40: 3 | B40: CI bootstrap theo file / bản ghi gốc, không theo bin.
A41: 4 | B41: Ngưỡng cảnh báo là ngưỡng thực hành, cần hiệu chỉnh theo dữ liệu của bạn.
A42: 5 | B42: Baseline chính thức là số của lib.so, không phải của Python – Parity phải Đạt trước, bắt đầu từ waveform sau resample/downmix.
A43: 6 | B43: Đo hiệu năng trên thiết bị đích, môi trường cố định; quy về mỗi phút audio; báo mean và p95.
A44: 7 | B44: Mọi tối ưu của lib phải qua Parity và KPI va Gate trước khi merge.
A45: 8 | B45: Decode nằm ngoài lib: kiểm tra ở Tich hop decode. Không tính vào gate của lib nhưng lệch timestamp ở đây làm lệch mọi segment.
...

Sheet Ke hoach baseline
A1: Kế hoạch xây baseline – chất lượng + hiệu năng lib.so
A2: Theo dõi từng bước. Vàng = bạn điền; trạng thái nhóm Q tự lấy từ sheet 'Quy trinh 8 buoc'. Cột 'Tiến độ hạn' tự tính.
A4: Mã | B4: Nhóm | C4: Bước | D4: Việc cần làm | E4: Đầu ra | F4: Tiêu chí hoàn thành | G4: Sheet chi tiết | H4: Phụ thuộc | I4: Phụ trách | J4: Bắt đầu | K4: Hạn | L4: Hoàn thành | M4: Trạng thái | N4: Tiến độ hạn | O4: Bằng chứng (link / file) | P4: Ghi chú
A5: 0.1 | B5: 0. Chuẩn bị | C5: Chốt target & KPI | D5: Chọn thiết bị/SoC đích, độ dài file điển hình và lớn nhất; đặt target cho từng KPI | E5: Cột Target trong KPI va Gate | F5: Mọi KPI có target hoặc ghi rõ "không đặt target" | G5: KPI va Gate | H5: – | I5: (tên) | J5: 46293 | K5: 46297 | M5: Chưa làm | N5: =IF(K5="","",IF(L5<>"",IF(L5>K5,"Xong trễ "&(L5-K5)&" ngày","Đúng hạn"),IF(OR(M5="Đạt",M5="Không áp dụng"),"",IF(TODAY()>K5,"Trễ "&(TODAY()-K5)&" ngày","Còn "&(K5-TODAY())&" ngày"))))
A6: 0.2 | B6: 0. Chuẩn bị | C6: Freeze baseline | D6: Ghi hash model, commit lib, resampler, downmix, cách gộp overlap, tham số và thứ tự hậu xử lý, version dữ liệu và script; gắn git tag | E6: Snapshot (cột Baseline) | F6: Mọi mục Snapshot có giá trị; có git tag | G6: Snapshot | H6: 0.1 | M6: Chưa làm | N6: =IF(K6="","",IF(L6<>"",IF(L6>K6,"Xong trễ "&(L6-K6)&" ngày","Đúng hạn"),IF(OR(M6="Đạt",M6="Không áp dụng"),"",IF(TODAY()>K6,"Trễ "&(TODAY()-K6)&" ngày","Còn "&(K6-TODAY())&" ngày"))))
A7: 0.3 | B7: 0. Chuẩn bị | C7: Hợp đồng input app ↔ lib | D7: Chốt sample rate, số kênh, kiểu mẫu và độ dài tối đa lib nhận; ai chịu trách nhiệm downmix | E7: Mục Input lib trong Snapshot | F7: App và lib cùng xác nhận | G7: Snapshot | H7: 0.1 | M7: Chưa làm | N7: =IF(K7="","",IF(L7<>"",IF(L7>K7,"Xong trễ "&(L7-K7)&" ngày","Đúng hạn"),IF(OR(M7="Đạt",M7="Không áp dụng"),"",IF(TODAY()>K7,"Trễ "&(TODAY()-K7)&" ngày","Còn "&(K7-TODAY())&" ngày"))))
A8: Q1 | B8: Q. Chất lượng offline | C8: ='Quy trinh 8 buoc'!B5 | D8: ='Quy trinh 8 buoc'!D5 | E8: ='Quy trinh 8 buoc'!E5 | F8: 0 nhóm vắt qua dev/test (mục 2a) | G8: Quy trinh 8 buoc | H8: 0.2 | M8: ='Quy trinh 8 buoc'!G5 | N8: =IF(K8="","",IF(L8<>"",IF(L8>K8,"Xong trễ "&(L8-K8)&" ngày","Đúng hạn"),IF(OR(M8="Đạt",M8="Không áp dụng"),"",IF(TODAY()>K8,"Trễ "&(TODAY()-K8)&" ngày","Còn "&(K8-TODAY())&" ngày")))) | O8: DL theo file (cột Tập)
A9: Q2 | B9: Q. Chất lượng offline | C9: ='Quy trinh 8 buoc'!B6 | D9: ='Quy trinh 8 buoc'!D6 | E9: ='Quy trinh 8 buoc'!E6 | F9: Bảng bin có đủ cột is_boundary, is_ambiguous, metadata | G9: Quy trinh 8 buoc | H9: Q1 | M9: ='Quy trinh 8 buoc'!G6 | N9: =IF(K9="","",IF(L9<>"",IF(L9>K9,"Xong trễ "&(L9-K9)&" ngày","Đúng hạn"),IF(OR(M9="Đạt",M9="Không áp dụng"),"",IF(TODAY()>K9,"Trễ "&(TODAY()-K9)&" ngày","Còn "&(K9-TODAY())&" ngày")))) | O9: DL theo file, DL nhan va phan bo
A10: Q3 | B10: Q. Chất lượng offline | C10: ='Quy trinh 8 buoc'!B7 | D10: ='Quy trinh 8 buoc'!D7 | E10: ='Quy trinh 8 buoc'!E7 | F10: Các mục 5a–5e, 2a–2c Đạt | G10: Kiem tra du lieu | H10: Q2 | M10: ='Quy trinh 8 buoc'!G7 | N10: =IF(K10="","",IF(L10<>"",IF(L10>K10,"Xong trễ "&(L10-K10)&" ngày","Đúng hạn"),IF(OR(M10="Đạt",M10="Không áp dụng"),"",IF(TODAY()>K10,"Trễ "&(TODAY()-K10)&" ngày","Còn "&(K10-TODAY())&" ngày")))) | O10: KQ du lieu that mục H; DL nhan va phan bo mục b; Hinh du lieu that, hình 1
A11: Q4 | B11: Q. Chất lượng offline | C11: ='Quy trinh 8 buoc'!B8 | D11: ='Quy trinh 8 buoc'!D8 | E11: ='Quy trinh 8 buoc'!E8 | F11: AUC, PR-AUC, DET có CI; báo trên 3 tập bin | G11: Quy trinh 8 buoc | H11: Q3 | M11: ='Quy trinh 8 buoc'!G8 | N11: =IF(K11="","",IF(L11<>"",IF(L11>K11,"Xong trễ "&(L11-K11)&" ngày","Đúng hạn"),IF(OR(M11="Đạt",M11="Không áp dụng"),"",IF(TODAY()>K11,"Trễ "&(TODAY()-K11)&" ngày","Còn "&(K11-TODAY())&" ngày")))) | O11: KQ du lieu that mục F; DL ROC
A12: Q5 | B12: Q. Chất lượng offline | C12: ='Quy trinh 8 buoc'!B9 | D12: ='Quy trinh 8 buoc'!D9 | E12: ='Quy trinh 8 buoc'!E9 | F12: Ngưỡng cố định + CI, ghi vào Snapshot | G12: Quy trinh 8 buoc | H12: Q4 | M12: ='Quy trinh 8 buoc'!G9 | N12: =IF(K12="","",IF(L12<>"",IF(L12>K12,"Xong trễ "&(L12-K12)&" ngày","Đúng hạn"),IF(OR(M12="Đạt",M12="Không áp dụng"),"",IF(TODAY()>K12,"Trễ "&(TODAY()-K12)&" ngày","Còn "&(K12-TODAY())&" ngày")))) | O12: KQ du lieu that mục A, E; DL quet nguong
A13: Q6 | B13: Q. Chất lượng offline | C13: ='Quy trinh 8 buoc'!B10 | D13: ='Quy trinh 8 buoc'!D10 | E13: ='Quy trinh 8 buoc'!E10 | F13: Bao cao category điền đủ, có CI | G13: Bao cao category | H13: Q5 | M13: ='Quy trinh 8 buoc'!G10 | N13: =IF(K13="","",IF(L13<>"",IF(L13>K13,"Xong trễ "&(L13-K13)&" ngày","Đúng hạn"),IF(OR(M13="Đạt",M13="Không áp dụng"),"",IF(TODAY()>K13,"Trễ "&(TODAY()-K13)&" ngày","Còn "&(K13-TODAY())&" ngày")))) | O13: KQ du lieu that mục B, C, I
A14: Q7 | B14: Q. Chất lượng offline | C14: ='Quy trinh 8 buoc'!B11 | D14: ='Quy trinh 8 buoc'!D11 | E14: ='Quy trinh 8 buoc'!E11 | F14: Bảng A0–A4 + heatmap F1(pad, merge) | G14: Ablation | H14: Q5 | M14: ='Quy trinh 8 buoc'!G11 | N14: =IF(K14="","",IF(L14<>"",IF(L14>K14,"Xong trễ "&(L14-K14)&" ngày","Đúng hạn"),IF(OR(M14="Đạt",M14="Không áp dụng"),"",IF(TODAY()>K14,"Trễ "&(TODAY()-K14)&" ngày","Còn "&(K14-TODAY())&" ngày")))) | O14: KQ du lieu that mục D; DL nhan va phan bo mục c; hình 3
A15: Q8 | B15: Q. Chất lượng offline | C15: ='Quy trinh 8 buoc'!B12 | D15: ='Quy trinh 8 buoc'!D12 | E15: ='Quy trinh 8 buoc'!E12 | F15: Có CI, per-category, top-K lỗi đã nghe | G15: Quy trinh 8 buoc | H15: Q6, Q7 | M15: ='Quy trinh 8 buoc'!G12 | N15: =IF(K15="","",IF(L15<>"",IF(L15>K15,"Xong trễ "&(L15-K15)&" ngày","Đúng hạn"),IF(OR(M15="Đạt",M15="Không áp dụng"),"",IF(TODAY()>K15,"Trễ "&(TODAY()-K15)&" ngày","Còn "&(K15-TODAY())&" ngày")))) | O15: KQ du lieu that; Hinh du lieu that; results_test/
A16: 1.1 | B16: 1. Chất lượng trên lib | C16: Parity Python ↔ lib | D16: Đưa cùng PCM vào Python reference và lib; so từ waveform sau resample/downmix đến F1 | E16: Parity mục B + danh sách file lệch | F16: Mọi mục PA Đạt với lib baseline | G16: Parity | H16: 0.2 | M16: Chưa làm | N16: =IF(K16="","",IF(L16<>"",IF(L16>K16,"Xong trễ "&(L16-K16)&" ngày","Đúng hạn"),IF(OR(M16="Đạt",M16="Không áp dụng"),"",IF(TODAY()>K16,"Trễ "&(TODAY()-K16)&" ngày","Còn "&(K16-TODAY())&" ngày"))))
A17: 1.2 | B17: 1. Chất lượng trên lib | C17: Tầng B trên output lib | D17: Chạy lại Bước 4–6 bằng output của lib; cập nhật Bao cao category – đây là số baseline chính thức | E17: Bao cao category (nguồn = lib) | F17: K01–K07 trong KPI va Gate lấy từ output lib | G17: Bao cao category | H17: 1.1, Q5 | M17: Chưa làm | N17: =IF(K17="","",IF(L17<>"",IF(L17>K17,"Xong trễ "&(L17-K17)&" ngày","Đúng hạn"),IF(OR(M17="Đạt",M17="Không áp dụng"),"",IF(TODAY()>K17,"Trễ "&(TODAY()-K17)&" ngày","Còn "&(K17-TODAY())&" ngày"))))
A18: 1.3 | B18: 1. Chất lượng trên lib | C18: Ablation gộp overlap, drop, thứ tự | D18: So các cách gộp score, quét drop, so thứ tự hậu xử lý; chọn cấu hình trên dev | E18: Ablation mục B, C, D | F18: Đã chọn và ghi vào Snapshot | G18: Ablation | H18: 1.2 | M18: Chưa làm | N18: =IF(K18="","",IF(L18<>"",IF(L18>K18,"Xong trễ "&(L18-K18)&" ngày","Đúng hạn"),IF(OR(M18="Đạt",M18="Không áp dụng"),"",IF(TODAY()>K18,"Trễ "&(TODAY()-K18)&" ngày","Còn "&(K18-TODAY())&" ngày"))))
A19: 2.1 | B19: 2. Hiệu năng | C19: Benchmark harness | D19: Tool C/C++ đọc PCM đã decode, gọi API lib, đo thời gian theo stage, xuất CSV | E19: Tool + script chạy lặp | F19: Hai lần chạy liên tiếp lệch < 5% | G19: Performance | H19: 0.2 | M19: Chưa làm | N19: =IF(K19="","",IF(L19<>"",IF(L19>K19,"Xong trễ "&(L19-K19)&" ngày","Đúng hạn"),IF(OR(M19="Đạt",M19="Không áp dụng"),"",IF(TODAY()>K19,"Trễ "&(TODAY()-K19)&" ngày","Còn "&(K19-TODAY())&" ngày"))))
A20: 2.2 | B20: 2. Hiệu năng | C20: Chuẩn hóa môi trường đo | D20: Cố định governor/tần số, core, số thread; định dạng PCM và tập file đo; warm-up; kiểm soát nhiệt | E20: Performance mục A | F20: Điền đủ mục A cho baseline | G20: Performance | H20: 2.1 | M20: Chưa làm | N20: =IF(K20="","",IF(L20<>"",IF(L20>K20,"Xong trễ "&(L20-K20)&" ngày","Đúng hạn"),IF(OR(M20="Đạt",M20="Không áp dụng"),"",IF(TODAY()>K20,"Trễ "&(TODAY()-K20)&" ngày","Còn "&(K20-TODAY())&" ngày"))))
A21: 2.3 | B21: 2. Hiệu năng | C21: Đo thời gian theo stage | D21: Downmix, resample, log-mel, inference, gộp overlap, hậu xử lý – ms cho mỗi phút audio; RTF; init | E21: Performance mục B, C | F21: Có số liệu đủ các stage và tổng | G21: Performance | H21: 2.2 | M21: Chưa làm | N21: =IF(K21="","",IF(L21<>"",IF(L21>K21,"Xong trễ "&(L21-K21)&" ngày","Đúng hạn"),IF(OR(M21="Đạt",M21="Không áp dụng"),"",IF(TODAY()>K21,"Trễ "&(TODAY()-K21)&" ngày","Còn "&(K21-TODAY())&" ngày"))))
A22: 2.4 | B22: 2. Hiệu năng | C22: Đo CPU & năng lượng | D22: Thời gian CPU / phút audio; công suất khi chạy và idle; rút sạc khi đo | E22: Performance mục D | F22: Hệ số biến thiên giữa các lần đo < 10% | G22: Performance | H22: 2.2 | M22: Chưa làm | N22: =IF(K22="","",IF(L22<>"",IF(L22>K22,"Xong trễ "&(L22-K22)&" ngày","Đúng hạn"),IF(OR(M22="Đạt",M22="Không áp dụng"),"",IF(TODAY()>K22,"Trễ "&(TODAY()-K22)&" ngày","Còn "&(K22-TODAY())&" ngày"))))
A23: 2.5 | B23: 2. Hiệu năng | C23: Đo bộ nhớ cố định & kích thước | D23: RSS do init, arena, kích thước model và .so | E23: Performance mục E | F23: Có số liệu đủ mục E | G23: Performance | H23: 2.2 | M23: Chưa làm | N23: =IF(K23="","",IF(L23<>"",IF(L23>K23,"Xong trễ "&(L23-K23)&" ngày","Đúng hạn"),IF(OR(M23="Đạt",M23="Không áp dụng"),"",IF(TODAY()>K23,"Trễ "&(TODAY()-K23)&" ngày","Còn "&(K23-TODAY())&" ngày"))))
A24: 3.1 | B24: 3. Biên, file dài & batch | C24: Nhãn mịn & độ chính xác biên | D24: Gán nhãn 10–20 ms cho tập con ~30–60 phút, đủ category; đo Δonset/Δoffset | E24: Tập nhãn mịn + Bien va timestamp mục A | F24: Có median và p95 cho Δonset, Δoffset | G24: Bien va timestamp | H24: Q2 | M24: Chưa làm | N24: =IF(K24="","",IF(L24<>"",IF(L24>K24,"Xong trễ "&(L24-K24)&" ngày","Đúng hạn"),IF(OR(M24="Đạt",M24="Không áp dụng"),"",IF(TODAY()>K24,"Trễ "&(TODAY()-K24)&" ngày","Còn "&(K24-TODAY())&" ngày"))))
A25: 3.2 | B25: 3. Biên, file dài & batch | C25: Vùng biên file & cửa sổ cuối | D25: Đo recall/FAR ở đầu, giữa, cuối file và phần dư < 0.96 s | E25: Bien va timestamp mục B | F25: Biết lib có mất speech ở cuối file không | G25: Bien va timestamp | H25: 1.2 | M25: Chưa làm | N25: =IF(K25="","",IF(L25<>"",IF(L25>K25,"Xong trễ "&(L25-K25)&" ngày","Đúng hạn"),IF(OR(M25="Đạt",M25="Không áp dụng"),"",IF(TODAY()>K25,"Trễ "&(TODAY()-K25)&" ngày","Còn "&(K25-TODAY())&" ngày"))))
A26: 3.3 | B26: 3. Biên, file dài & batch | C26: Căn chỉnh thời gian của lib | D26: Quét shift ±1 s trên output lib; kiểm số cửa sổ và segment trong biên file | E26: Bien va timestamp mục C | F26: Lệch đỉnh F1 = 0; 0 segment vượt biên | G26: Bien va timestamp | H26: 1.1 | M26: Chưa làm | N26: =IF(K26="","",IF(L26<>"",IF(L26>K26,"Xong trễ "&(L26-K26)&" ngày","Đúng hạn"),IF(OR(M26="Đạt",M26="Không áp dụng"),"",IF(TODAY()>K26,"Trễ "&(TODAY()-K26)&" ngày","Còn "&(K26-TODAY())&" ngày"))))
A27: 3.4 | B27: 3. Biên, file dài & batch | C27: Theo độ dài file | D27: Chạy file 1, 10, 60, 180, 480 phút; ghi thời gian và peak RSS | E27: File dai va batch mục A | F27: Biết độ dài tối đa chạy được và độ dốc RAM | G27: File dai va batch | H27: 2.1 | M27: Chưa làm | N27: =IF(K27="","",IF(L27<>"",IF(L27>K27,"Xong trễ "&(L27-K27)&" ngày","Đúng hạn"),IF(OR(M27="Đạt",M27="Không áp dụng"),"",IF(TODAY()>K27,"Trễ "&(TODAY()-K27)&" ngày","Còn "&(K27-TODAY())&" ngày"))))
... A38: 6.3 | B38: 6. Tích hợp decode (ngoài lib) | C38: Chi phí decode (tùy chọn) | D38: Thời gian và RAM decode so với thời gian lib | E38: Tich hop decode mục D | F38: Có số liệu | G38: Tich hop decode | H38: 2.3 | M38: Chưa làm | N38: =IF(K38="","",IF(L38<>"",IF(L38>K38,"Xong trễ "&(L38-K38)&" ngày","Đúng hạn"),IF(OR(M38="Đạt",M38="Không áp dụng"),"",IF(TODAY()>K38,"Trễ "&(TODAY()-K38)&" ngày","Còn "&(K38-TODAY())&" ngày"))))
C40: Tiến độ theo nhóm
C41: Nhóm | D41: Số bước | E41: Đạt | F41: Đang làm | G41: Không đạt | H41: Không áp dụng | I41: Tiến độ
C42: 0. Chuẩn bị | D42: =COUNTIF($B$5:$B$38,C42) | E42: =COUNTIFS($B$5:$B$38,$C42,$M$5:$M$38,"Đạt") | F42: =COUNTIFS($B$5:$B$38,$C42,$M$5:$M$38,"Đang làm") | G42: =COUNTIFS($B$5:$B$38,$C42,$M$5:$M$38,"Không đạt") | H42: =COUNTIFS($B$5:$B$38,$C42,$M$5:$M$38,"Không áp dụng") | I42: =IFERROR(E42/(D42-H42),0)
C43: Q. Chất lượng offline | D43: =COUNTIF($B$5:$B$38,C43) | E43: =COUNTIFS($B$5:$B$38,$C43,$M$5:$M$38,"Đạt") | F43: =COUNTIFS($B$5:$B$38,$C43,$M$5:$M$38,"Đang làm") | G43: =COUNTIFS($B$5:$B$38,$C43,$M$5:$M$38,"Không đạt") | H43: =COUNTIFS($B$5:$B$38,$C43,$M$5:$M$38,"Không áp dụng") | I43: =IFERROR(E43/(D43-H43),0)
C44: 1. Chất lượng trên lib | D44: =COUNTIF($B$5:$B$38,C44) | E44: =COUNTIFS($B$5:$B$38,$C44,$M$5:$M$38,"Đạt") | F44: =COUNTIFS($B$5:$B$38,$C44,$M$5:$M$38,"Đang làm") | G44: =COUNTIFS($B$5:$B$38,$C44,$M$5:$M$38,"Không đạt") | H44: =COUNTIFS($B$5:$B$38,$C44,$M$5:$M$38,"Không áp dụng") | I44: =IFERROR(E44/(D44-H44),0)
C45: 2. Hiệu năng | D45: =COUNTIF($B$5:$B$38,C45) | E45: =COUNTIFS($B$5:$B$38,$C45,$M$5:$M$38,"Đạt") | F45: =COUNTIFS($B$5:$B$38,$C45,$M$5:$M$38,"Đang làm") | G45: =COUNTIFS($B$5:$B$38,$C45,$M$5:$M$38,"Không đạt") | H45: =COUNTIFS($B$5:$B$38,$C45,$M$5:$M$38,"Không áp dụng") | I45: =IFERROR(E45/(D45-H45),0)
C46: 3. Biên, file dài & batch | D46: =COUNTIF($B$5:$B$38,C46) | E46: =COUNTIFS($B$5:$B$38,$C46,$M$5:$M$38,"Đạt") | F46: =COUNTIFS($B$5:$B$38,$C46,$M$5:$M$38,"Đang làm") | G46: =COUNTIFS($B$5:$B$38,$C46,$M$5:$M$38,"Không đạt") | H46: =COUNTIFS($B$5:$B$38,$C46,$M$5:$M$38,"Không áp dụng") | I46: =IFERROR(E46/(D46-H46),0)
C47: 4. Độ bền & chức năng | D47: =COUNTIF($B$5:$B$38,C47) | E47: =COUNTIFS($B$5:$B$38,$C47,$M$5:$M$38,"Đạt") | F47: =COUNTIFS($B$5:$B$38,$C47,$M$5:$M$38,"Đang làm") | G47: =COUNTIFS($B$5:$B$38,$C47,$M$5:$M$38,"Không đạt") | H47: =COUNTIFS($B$5:$B$38,$C47,$M$5:$M$38,"Không áp dụng") | I47: =IFERROR(E47/(D47-H47),0)
C48: 5. So sánh & chốt | D48: =COUNTIF($B$5:$B$38,C48) | E48: =COUNTIFS($B$5:$B$38,$C48,$M$5:$M$38,"Đạt") | F48: =COUNTIFS($B$5:$B$38,$C48,$M$5:$M$38,"Đang làm") | G48: =COUNTIFS($B$5:$B$38,$C48,$M$5:$M$38,"Không đạt") | H48: =COUNTIFS($B$5:$B$38,$C48,$M$5:$M$38,"Không áp dụng") | I48: =IFERROR(E48/(D48-H48),0)
C49: 6. Tích hợp decode (ngoài lib) | D49: =COUNTIF($B$5:$B$38,C49) | E49: =COUNTIFS($B$5:$B$38,$C49,$M$5:$M$38,"Đạt") | F49: =COUNTIFS($B$5:$B$38,$C49,$M$5:$M$38,"Đang làm") | G49: =COUNTIFS($B$5:$B$38,$C49,$M$5:$M$38,"Không đạt") | H49: =COUNTIFS($B$5:$B$38,$C49,$M$5:$M$38,"Không áp dụng") | I49: =IFERROR(E49/(D49-H49),0)
C50: Tổng | D50: =SUM(D42:D49) | E50: =SUM(E42:E49) | F50: =SUM(F42:F49) | G50: =SUM(G42:G49) | H50: =SUM(H42:H49) | I50: =IFERROR(E50/(D50-H50),0)
C51: Số bước đang trễ hạn | D51: =COUNTIF(N5:N38,"Trễ *")

Sheet KPI va Gate
A1: KPI và regression gate của lib – baseline vs candidate
A2: Baseline/candidate tự lấy từ sheet nguồn (chữ đen) hoặc bạn điền (vàng). Hướng tốt: Cao = càng cao càng tốt. Dung sai = mức xấu đi tối đa so với baseline, cùng đơn vị. Decode không tính vào gate.
A4: Mã | B4: Nhóm | C4: KPI | D4: Đơn vị | E4: Hướng tốt | F4: Baseline | G4: Candidate | H4: Δ | I4: Δ % | J4: Target | K4: Dung sai | L4: Đạt target? | M4: Không thụt lùi? | N4: Kết luận | O4: CI Δ thấp | P4: CI Δ cao | Q4: Δ có ý nghĩa? | R4: Nguồn | S4: Ghi chú
A5: K01 | B5: Chất lượng | C5: F1 strict (macro, output lib) | D5: – | E5: Cao | F5: =IF('Bao cao category'!J15="","",'Bao cao category'!J15) | H5: =IF(OR(F5="",G5=""),"",G5-F5) | I5: =IF(OR(F5="",G5=""),"",IFERROR((G5-F5)/ABS(F5),"")) | K5: 0.005 | L5: =IF(OR(G5="",J5=""),"",IF(E5="Thấp",IF(G5<=J5,"Có","Không"),IF(G5>=J5,"Có","Không"))) | M5: =IF(OR(F5="",G5="",K5=""),"",IF(E5="Thấp",IF(G5<=F5+K5,"Có","Không"),IF(G5>=F5-K5,"Có","Không"))) | N5: =IF(G5="","Chưa đo",IF(OR(L5="Không",M5="Không"),"Không đạt",IF(AND(L5="",M5=""),"Chưa có tiêu chí","Đạt"))) | Q5: =IF(OR(O5="",P5=""),"",IF(OR(O5>0,P5<0),"Có","Không")) | R5: Bao cao category | S5: ="F1 gộp toàn test = "&FIXED('KQ du lieu that'!$S$37,3)&"; ô Baseline = TB 5 category. Ngưỡng "&FIXED('KQ du lieu that'!$B$11,2)&" ("&'KQ du lieu that'!$B$8&" dev, "&'KQ du lieu that'!$B$7&")"
A6: K02 | B6: Chất lượng | C6: F1 ±1 bin (macro) | D6: – | E6: Cao | F6: =IF('Bao cao category'!K15="","",'Bao cao category'!K15) | H6: =IF(OR(F6="",G6=""),"",G6-F6) | I6: =IF(OR(F6="",G6=""),"",IFERROR((G6-F6)/ABS(F6),"")) | K6: 0.005 | L6: =IF(OR(G6="",J6=""),"",IF(E6="Thấp",IF(G6<=J6,"Có","Không"),IF(G6>=J6,"Có","Không"))) | M6: =IF(OR(F6="",G6="",K6=""),"",IF(E6="Thấp",IF(G6<=F6+K6,"Có","Không"),IF(G6>=F6-K6,"Có","Không"))) | N6: =IF(G6="","Chưa đo",IF(OR(L6="Không",M6="Không"),"Không đạt",IF(AND(L6="",M6=""),"Chưa có tiêu chí","Đạt"))) | Q6: =IF(OR(O6="",P6=""),"",IF(OR(O6>0,P6<0),"Có","Không")) | R6: Bao cao category | S6: ="F1 ±1 bin gộp = "&FIXED('KQ du lieu that'!$T$37,3)
A7: K03 | B7: Chất lượng | C7: DCF (macro) | D7: – | E7: Thấp | F7: =IF('Bao cao category'!N15="","",'Bao cao category'!N15) | H7: =IF(OR(F7="",G7=""),"",G7-F7) | I7: =IF(OR(F7="",G7=""),"",IFERROR((G7-F7)/ABS(F7),"")) | K7: 0.005 | L7: =IF(OR(G7="",J7=""),"",IF(E7="Thấp",IF(G7<=J7,"Có","Không"),IF(G7>=J7,"Có","Không"))) | M7: =IF(OR(F7="",G7="",K7=""),"",IF(E7="Thấp",IF(G7<=F7+K7,"Có","Không"),IF(G7>=F7-K7,"Có","Không"))) | N7: =IF(G7="","Chưa đo",IF(OR(L7="Không",M7="Không"),"Không đạt",IF(AND(L7="",M7=""),"Chưa có tiêu chí","Đạt"))) | Q7: =IF(OR(O7="",P7=""),"",IF(OR(O7>0,P7<0),"Có","Không")) | R7: Bao cao category | S7: ="DCF gộp = "&FIXED('KQ du lieu that'!$U$37,3)&" (trọng số miss "&FIXED('KQ du lieu that'!$B$6,2)&")"
A8: K04 | B8: Chất lượng | C8: Miss rate (macro) | D8: % | E8: Thấp | F8: =IF('Bao cao category'!D15="","",'Bao cao category'!D15) | H8: =IF(OR(F8="",G8=""),"",G8-F8) | I8: =IF(OR(F8="",G8=""),"",IFERROR((G8-F8)/ABS(F8),"")) | K8: 0.01 | L8: =IF(OR(G8="",J8=""),"",IF(E8="Thấp",IF(G8<=J8,"Có","Không"),IF(G8>=J8,"Có","Không"))) | M8: =IF(OR(F8="",G8="",K8=""),"",IF(E8="Thấp",IF(G8<=F8+K8,"Có","Không"),IF(G8>=F8-K8,"Có","Không"))) | N8: =IF(G8="","Chưa đo",IF(OR(L8="Không",M8="Không"),"Không đạt",IF(AND(L8="",M8=""),"Chưa có tiêu chí","Đạt"))) | Q8: =IF(OR(O8="",P8=""),"",IF(OR(O8>0,P8<0),"Có","Không")) | R8: Bao cao category | S8: ="MR gộp = "&FIXED('KQ du lieu that'!$P$37*100,1)&"%"
A9: K05 | B9: Chất lượng | C9: False alarm rate (macro) | D9: % | E9: Thấp | F9: =IF('Bao cao category'!E15="","",'Bao cao category'!E15) | H9: =IF(OR(F9="",G9=""),"",G9-F9) | I9: =IF(OR(F9="",G9=""),"",IFERROR((G9-F9)/ABS(F9),"")) | K9: 0.01 | L9: =IF(OR(G9="",J9=""),"",IF(E9="Thấp",IF(G9<=J9,"Có","Không"),IF(G9>=J9,"Có","Không"))) | M9: =IF(OR(F9="",G9="",K9=""),"",IF(E9="Thấp",IF(G9<=F9+K9,"Có","Không"),IF(G9>=F9-K9,"Có","Không"))) | N9: =IF(G9="","Chưa đo",IF(OR(L9="Không",M9="Không"),"Không đạt",IF(AND(L9="",M9=""),"Chưa có tiêu chí","Đạt"))) | Q9: =IF(OR(O9="",P9=""),"",IF(OR(O9>0,P9<0),"Có","Không")) | R9: Bao cao category | S9: ="FAR gộp = "&FIXED('KQ du lieu that'!$Q$37*100,1)&"%"
A10: K06 | B10: Chất lượng | C10: ROC-AUC tầng A (output lib) | D10: – | E10: Cao | F10: ='KQ du lieu that'!$D$59 | H10: =IF(OR(F10="",G10=""),"",G10-F10) | I10: =IF(OR(F10="",G10=""),"",IFERROR((G10-F10)/ABS(F10),"")) | K10: 0.002 | L10: =IF(OR(G10="",J10=""),"",IF(E10="Thấp",IF(G10<=J10,"Có","Không"),IF(G10>=J10,"Có","Không"))) | M10: =IF(OR(F10="",G10="",K10=""),"",IF(E10="Thấp",IF(G10<=F10+K10,"Có","Không"),IF(G10>=F10-K10,"Có","Không"))) | N10: =IF(G10="","Chưa đo",IF(OR(L10="Không",M10="Không"),"Không đạt",IF(AND(L10="",M10=""),"Chưa có tiêu chí","Đạt"))) | Q10: =IF(OR(O10="",P10=""),"",IF(OR(O10>0,P10<0),"Có","Không")) | R10: Bước 4 | S10: ="AUC hình thang (công thức); Python chính xác = "&FIXED('KQ du lieu that'!$E$59,3)&", CI95 "&FIXED('KQ du lieu that'!$B$67,3)&"–"&FIXED('KQ du lieu that'!$C$67,3)
A11: K07 | B11: Chất lượng | C11: Event-F1 (collar 0.5 s) – output cuối là segment | D11: – | E11: Cao | F11: ='KQ du lieu that'!$C$92 | H11: =IF(OR(F11="",G11=""),"",G11-F11) | I11: =IF(OR(F11="",G11=""),"",IFERROR((G11-F11)/ABS(F11),"")) | K11: 0.01 | L11: =IF(OR(G11="",J11=""),"",IF(E11="Thấp",IF(G11<=J11,"Có","Không"),IF(G11>=J11,"Có","Không"))) | M11: =IF(OR(F11="",G11="",K11=""),"",IF(E11="Thấp",IF(G11<=F11+K11,"Có","Không"),IF(G11>=F11-K11,"Có","Không"))) | N11: =IF(G11="","Chưa đo",IF(OR(L11="Không",M11="Không"),"Không đạt",IF(AND(L11="",M11=""),"Chưa có tiêu chí","Đạt"))) | Q11: =IF(OR(O11="",P11=""),"",IF(OR(O11>0,P11<0),"Có","Không")) | R11: Bước 6 | S11: ="Python ở ngưỡng "&FIXED('KQ du lieu that'!$B$12,2)&"; phụ thuộc cách nhãn cắt đoạn"
A12: K08 | B12: Biên & file | C12: |Δonset| p95 trên nhãn mịn | D12: ms | E12: Thấp | F12: =IF('Bien va timestamp'!C9="","",'Bien va timestamp'!C9) | G12: =IF('Bien va timestamp'!D9="","",'Bien va timestamp'!D9) | H12: =IF(OR(F12="",G12=""),"",G12-F12) | I12: =IF(OR(F12="",G12=""),"",IFERROR((G12-F12)/ABS(F12),"")) | K12: 20 | L12: =IF(OR(G12="",J12=""),"",IF(E12="Thấp",IF(G12<=J12,"Có","Không"),IF(G12>=J12,"Có","Không"))) | M12: =IF(OR(F12="",G12="",K12=""),"",IF(E12="Thấp",IF(G12<=F12+K12,"Có","Không"),IF(G12>=F12-K12,"Có","Không"))) | N12: =IF(G12="","Chưa đo",IF(OR(L12="Không",M12="Không"),"Không đạt",IF(AND(L12="",M12=""),"Chưa có tiêu chí","Đạt"))) | Q12: =IF(OR(O12="",P12=""),"",IF(OR(O12>0,P12<0),"Có","Không")) | R12: Bien va timestamp
A13: K09 | B13: Biên & file | C13: |Δoffset| p95 trên nhãn mịn | D13: ms | E13: Thấp | F13: =IF('Bien va timestamp'!C11="","",'Bien va timestamp'!C11) | G13: =IF('Bien va timestamp'!D11="","",'Bien va timestamp'!D11) | H13: =IF(OR(F13="",G13=""),"",G13-F13) | I13: =IF(OR(F13="",G13=""),"",IFERROR((G13-F13)/ABS(F13),"")) | K13: 20 | L13: =IF(OR(G13="",J13=""),"",IF(E13="Thấp",IF(G13<=J13,"Có","Không"),IF(G13>=J13,"Có","Không"))) | M13: =IF(OR(F13="",G13="",K13=""),"",IF(E13="Thấp",IF(G13<=F13+K13,"Có","Không"),IF(G13>=F13-K13,"Có","Không"))) | N13: =IF(G13="","Chưa đo",IF(OR(L13="Không",M13="Không"),"Không đạt",IF(AND(L13="",M13=""),"Chưa có tiêu chí","Đạt"))) | Q13: =IF(OR(O13="",P13=""),"",IF(OR(O13>0,P13<0),"Có","Không")) | R13: Bien va timestamp
A14: K10 | B14: Biên & file | C14: Recall 1 s cuối file | D14: % | E14: Cao | F14: =IF('Bien va timestamp'!B18="","",'Bien va timestamp'!B18) | G14: =IF('Bien va timestamp'!D18="","",'Bien va timestamp'!D18) | H14: =IF(OR(F14="",G14=""),"",G14-F14) | I14: =IF(OR(F14="",G14=""),"",IFERROR((G14-F14)/ABS(F14),"")) | K14: 0.02 | L14: =IF(OR(G14="",J14=""),"",IF(E14="Thấp",IF(G14<=J14,"Có","Không"),IF(G14>=J14,"Có","Không"))) | M14: =IF(OR(F14="",G14="",K14=""),"",IF(E14="Thấp",IF(G14<=F14+K14,"Có","Không"),IF(G14>=F14-K14,"Có","Không"))) | N14: =IF(G14="","Chưa đo",IF(OR(L14="Không",M14="Không"),"Không đạt",IF(AND(L14="",M14=""),"Chưa có tiêu chí","Đạt"))) | Q14: =IF(OR(O14="",P14=""),"",IF(OR(O14>0,P14<0),"Có","Không")) | R14: Bien va timestamp
A15: K11 | B15: Biên & file | C15: Lệch đỉnh F1 khi quét shift | D15: ms | E15: Thấp | F15: =IF('Bien va timestamp'!C24="","",'Bien va timestamp'!C24) | G15: =IF('Bien va timestamp'!D24="","",'Bien va timestamp'!D24) | H15: =IF(OR(F15="",G15=""),"",G15-F15) | I15: =IF(OR(F15="",G15=""),"",IFERROR((G15-F15)/ABS(F15),"")) | K15: 0 | L15: =IF(OR(G15="",J15=""),"",IF(E15="Thấp",IF(G15<=J15,"Có","Không"),IF(G15>=J15,"Có","Không"))) | M15: =IF(OR(F15="",G15="",K15=""),"",IF(E15="Thấp",IF(G15<=F15+K15,"Có","Không"),IF(G15>=F15-K15,"Có","Không"))) | N15: =IF(G15="","Chưa đo",IF(OR(L15="Không",M15="Không"),"Không đạt",IF(AND(L15="",M15=""),"Chưa có tiêu chí","Đạt"))) | Q15: =IF(OR(O15="",P15=""),"",IF(OR(O15>0,P15<0),"Có","Không")) | R15: Bien va timestamp | S15: Đo trên output Python; xem comment Bien va timestamp!C24.
A16: K12 | B16: Biên & file | C16: FA/giờ trên audio không lời | D16: lần/giờ | E16: Thấp | F16: =IF('File dai va batch'!D37="","",'File dai va batch'!D37) | G16: =IF('File dai va batch'!F37="","",'File dai va batch'!F37) | H16: =IF(OR(F16="",G16=""),"",G16-F16) | I16: =IF(OR(F16="",G16=""),"",IFERROR((G16-F16)/ABS(F16),"")) | K16: 0.5 | L16: =IF(OR(G16="",J16=""),"",IF(E16="Thấp",IF(G16<=J16,"Có","Không"),IF(G16>=J16,"Có","Không"))) | M16: =IF(OR(F16="",G16="",K16=""),"",IF(E16="Thấp",IF(G16<=F16+K16,"Có","Không"),IF(G16>=F16-K16,"Có","Không"))) | N16: =IF(G16="","Chưa đo",IF(OR(L16="Không",M16="Không"),"Không đạt",IF(AND(L16="",M16=""),"Chưa có tiêu chí","Đạt"))) | Q16: =IF(OR(O16="",P16=""),"",IF(OR(O16>0,P16<0),"Có","Không")) | R16: File dai va batch
A17: K13 | B17: Độ bền | C17: F1 thấp nhất trong robustness sweep | D17: – | E17: Cao | F17: =Robustness!C31 | G17: =Robustness!C32 | H17: =IF(OR(F17="",G17=""),"",G17-F17) | I17: =IF(OR(F17="",G17=""),"",IFERROR((G17-F17)/ABS(F17),"")) | K17: 0.01 | L17: =IF(OR(G17="",J17=""),"",IF(E17="Thấp",IF(G17<=J17,"Có","Không"),IF(G17>=J17,"Có","Không"))) | M17: =IF(OR(F17="",G17="",K17=""),"",IF(E17="Thấp",IF(G17<=F17+K17,"Có","Không"),IF(G17>=F17-K17,"Có","Không"))) | N17: =IF(G17="","Chưa đo",IF(OR(L17="Không",M17="Không"),"Không đạt",IF(AND(L17="",M17=""),"Chưa có tiêu chí","Đạt"))) | Q17: =IF(OR(O17="",P17=""),"",IF(OR(O17>0,P17<0),"Có","Không")) | R17: Robustness
A18: K14 | B18: Độ bền | C18: Parity: % bin khác Python sau hậu xử lý | D18: % | E18: Thấp | F18: =IF(Parity!F20="","",Parity!F20) | G18: =IF(Parity!H20="","",Parity!H20) | H18: =IF(OR(F18="",G18=""),"",G18-F18) | I18: =IF(OR(F18="",G18=""),"",IFERROR((G18-F18)/ABS(F18),"")) | K18: 0.001 | L18: =IF(OR(G18="",J18=""),"",IF(E18="Thấp",IF(G18<=J18,"Có","Không"),IF(G18>=J18,"Có","Không"))) | M18: =IF(OR(F18="",G18="",K18=""),"",IF(E18="Thấp",IF(G18<=F18+K18,"Có","Không"),IF(G18>=F18-K18,"Có","Không"))) | N18: =IF(G18="","Chưa đo",IF(OR(L18="Không",M18="Không"),"Không đạt",IF(AND(L18="",M18=""),"Chưa có tiêu chí","Đạt"))) | Q18: =IF(OR(O18="",P18=""),"",IF(OR(O18>0,P18<0),"Có","Không")) | R18: Parity
A19: K15 | B19: Độ bền | C19: Test chức năng Không đạt (khi đã chạy hết) | D19: test | E19: Thấp | F19: =IF('Test chuc nang'!F39>0,"",'Test chuc nang'!F38) | G19: =IF('Test chuc nang'!G39>0,"",'Test chuc nang'!G38) | H19: =IF(OR(F19="",G19=""),"",G19-F19) | I19: =IF(OR(F19="",G19=""),"",IFERROR((G19-F19)/ABS(F19),"")) | K19: 0 | L19: =IF(OR(G19="",J19=""),"",IF(E19="Thấp",IF(G19<=J19,"Có","Không"),IF(G19>=J19,"Có","Không"))) | M19: =IF(OR(F19="",G19="",K19=""),"",IF(E19="Thấp",IF(G19<=F19+K19,"Có","Không"),IF(G19>=F19-K19,"Có","Không"))) | N19: =IF(G19="","Chưa đo",IF(OR(L19="Không",M19="Không"),"Không đạt",IF(AND(L19="",M19=""),"Chưa có tiêu chí","Đạt"))) | Q19: =IF(OR(O19="",P19=""),"",IF(OR(O19>0,P19<0),"Có","Không")) | R19: Test chuc nang
A20: K16 | B20: Hiệu năng | C20: RTF mean | D20: – | E20: Thấp | F20: =IF(Performance!C36="","",Performance!C36) | G20: =IF(Performance!F36="","",Performance!F36) | H20: =IF(OR(F20="",G20=""),"",G20-F20) | I20: =IF(OR(F20="",G20=""),"",IFERROR((G20-F20)/ABS(F20),"")) | K20: 0.005 | L20: =IF(OR(G20="",J20=""),"",IF(E20="Thấp",IF(G20<=J20,"Có","Không"),IF(G20>=J20,"Có","Không"))) | M20: =IF(OR(F20="",G20="",K20=""),"",IF(E20="Thấp",IF(G20<=F20+K20,"Có","Không"),IF(G20>=F20-K20,"Có","Không"))) | N20: =IF(G20="","Chưa đo",IF(OR(L20="Không",M20="Không"),"Không đạt",IF(AND(L20="",M20=""),"Chưa có tiêu chí","Đạt"))) | Q20: =IF(OR(O20="",P20=""),"",IF(OR(O20>0,P20<0),"Có","Không")) | R20: Performance
A21: K17 | B21: Hiệu năng | C21: RTF p95 | D21: – | E21: Thấp | F21: =IF(Performance!C37="","",Performance!C37) | G21: =IF(Performance!F37="","",Performance!F37) | H21: =IF(OR(F21="",G21=""),"",G21-F21) | I21: =IF(OR(F21="",G21=""),"",IFERROR((G21-F21)/ABS(F21),"")) | K21: 0.005 | L21: =IF(OR(G21="",J21=""),"",IF(E21="Thấp",IF(G21<=J21,"Có","Không"),IF(G21>=J21,"Có","Không"))) | M21: =IF(OR(F21="",G21="",K21=""),"",IF(E21="Thấp",IF(G21<=F21+K21,"Có","Không"),IF(G21>=F21-K21,"Có","Không"))) | N21: =IF(G21="","Chưa đo",IF(OR(L21="Không",M21="Không"),"Không đạt",IF(AND(L21="",M21=""),"Chưa có tiêu chí","Đạt"))) | Q21: =IF(OR(O21="",P21=""),"",IF(OR(O21>0,P21<0),"Có","Không")) | R21: Performance
A22: K18 | B22: Hiệu năng | C22: Thời gian CPU cho 1 phút audio | D22: s | E22: Thấp | F22: =IF(Performance!C46="","",Performance!C46) | G22: =IF(Performance!F46="","",Performance!F46) | H22: =IF(OR(F22="",G22=""),"",G22-F22) | I22: =IF(OR(F22="",G22=""),"",IFERROR((G22-F22)/ABS(F22),"")) | K22: 0.2 | L22: =IF(OR(G22="",J22=""),"",IF(E22="Thấp",IF(G22<=J22,"Có","Không"),IF(G22>=J22,"Có","Không"))) | M22: =IF(OR(F22="",G22="",K22=""),"",IF(E22="Thấp",IF(G22<=F22+K22,"Có","Không"),IF(G22>=F22-K22,"Có","Không"))) | N22: =IF(G22="","Chưa đo",IF(OR(L22="Không",M22="Không"),"Không đạt",IF(AND(L22="",M22=""),"Chưa có tiêu chí","Đạt"))) | Q22: =IF(OR(O22="",P22=""),"",IF(OR(O22>0,P22<0),"Có","Không")) | R22: Performance
A23: K19 | B23: Hiệu năng | C23: Năng lượng cho 1 phút audio | D23: J | E23: Thấp | F23: =IF(Performance!C51="","",Performance!C51) | G23: =IF(Performance!F51="","",Performance!F51) | H23: =IF(OR(F23="",G23=""),"",G23-F23) | I23: =IF(OR(F23="",G23=""),"",IFERROR((G23-F23)/ABS(F23),"")) | K23: 0.5 | L23: =IF(OR(G23="",J23=""),"",IF(E23="Thấp",IF(G23<=J23,"Có","Không"),IF(G23>=J23,"Có","Không"))) | M23: =IF(OR(F23="",G23="",K23=""),"",IF(E23="Thấp",IF(G23<=F23+K23,"Có","Không"),IF(G23>=F23-K23,"Có","Không"))) | N23: =IF(G23="","Chưa đo",IF(OR(L23="Không",M23="Không"),"Không đạt",IF(AND(L23="",M23=""),"Chưa có tiêu chí","Đạt"))) | Q23: =IF(OR(O23="",P23=""),"",IF(OR(O23>0,P23<0),"Có","Không")) | R23: Performance
A24: K20 | B24: Hiệu năng | C24: Peak RSS với file 60 phút | D24: MB | E24: Thấp | F24: =IF('File dai va batch'!C23="","",'File dai va batch'!C23) | G24: =IF('File dai va batch'!D23="","",'File dai va batch'!D23) | H24: =IF(OR(F24="",G24=""),"",G24-F24) | I24: =IF(OR(F24="",G24=""),"",IFERROR((G24-F24)/ABS(F24),"")) | K24: 5 | L24: =IF(OR(G24="",J24=""),"",IF(E24="Thấp",IF(G24<=J24,"Có","Không"),IF(G24>=J24,"Có","Không"))) | M24: =IF(OR(F24="",G24="",K24=""),"",IF(E24="Thấp",IF(G24<=F24+K24,"Có","Không"),IF(G24>=F24-K24,"Có","Không"))) | N24: =IF(G24="","Chưa đo",IF(OR(L24="Không",M24="Không"),"Không đạt",IF(AND(L24="",M24=""),"Chưa có tiêu chí","Đạt"))) | Q24: =IF(OR(O24="",P24=""),"",IF(OR(O24>0,P24<0),"Có","Không")) | R24: File dai va batch
A25: K21 | B25: Hiệu năng | C25: RSS tăng theo độ dài file | D25: MB/phút | E25: Thấp | F25: =IF('File dai va batch'!C22="","",'File dai va batch'!C22) | G25: =IF('File dai va batch'!D22="","",'File dai va batch'!D22) | H25: =IF(OR(F25="",G25=""),"",G25-F25) | I25: =IF(OR(F25="",G25=""),"",IFERROR((G25-F25)/ABS(F25),"")) | K25: 0.1 | L25: =IF(OR(G25="",J25=""),"",IF(E25="Thấp",IF(G25<=J25,"Có","Không"),IF(G25>=J25,"Có","Không"))) | M25: =IF(OR(F25="",G25="",K25=""),"",IF(E25="Thấp",IF(G25<=F25+K25,"Có","Không"),IF(G25>=F25-K25,"Có","Không"))) | N25: =IF(G25="","Chưa đo",IF(OR(L25="Không",M25="Không"),"Không đạt",IF(AND(L25="",M25=""),"Chưa có tiêu chí","Đạt"))) | Q25: =IF(OR(O25="",P25=""),"",IF(OR(O25>0,P25<0),"Có","Không")) | R25: File dai va batch
A26: K22 | B26: Hiệu năng | C26: RSS tăng mỗi 100 file | D26: MB | E26: Thấp | F26: =IF('File dai va batch'!C25="","",'File dai va batch'!C25) | G26: =IF('File dai va batch'!D25="","",'File dai va batch'!D25) | H26: =IF(OR(F26="",G26=""),"",G26-F26) | I26: =IF(OR(F26="",G26=""),"",IFERROR((G26-F26)/ABS(F26),"")) | K26: 0.5 | L26: =IF(OR(G26="",J26=""),"",IF(E26="Thấp",IF(G26<=J26,"Có","Không"),IF(G26>=J26,"Có","Không"))) | M26: =IF(OR(F26="",G26="",K26=""),"",IF(E26="Thấp",IF(G26<=F26+K26,"Có","Không"),IF(G26>=F26-K26,"Có","Không"))) | N26: =IF(G26="","Chưa đo",IF(OR(L26="Không",M26="Không"),"Không đạt",IF(AND(L26="",M26=""),"Chưa có tiêu chí","Đạt"))) | Q26: =IF(OR(O26="",P26=""),"",IF(OR(O26>0,P26<0),"Có","Không")) | R26: File dai va batch
A27: K23 | B27: Hiệu năng | C27: Kích thước lib.so | D27: KB | E27: Thấp | F27: =IF(Performance!C61="","",Performance!C61) | G27: =IF(Performance!F61="","",Performance!F61) | H27: =IF(OR(F27="",G27=""),"",G27-F27) | I27: =IF(OR(F27="",G27=""),"",IFERROR((G27-F27)/ABS(F27),"")) | K27: 0 | L27: =IF(OR(G27="",J27=""),"",IF(E27="Thấp",IF(G27<=J27,"Có","Không"),IF(G27>=J27,"Có","Không"))) | M27: =IF(OR(F27="",G27="",K27=""),"",IF(E27="Thấp",IF(G27<=F27+K27,"Có","Không"),IF(G27>=F27-K27,"Có","Không"))) | N27: =IF(G27="","Chưa đo",IF(OR(L27="Không",M27="Không"),"Không đạt",IF(AND(L27="",M27=""),"Chưa có tiêu chí","Đạt"))) | Q27: =IF(OR(O27="",P27=""),"",IF(OR(O27>0,P27<0),"Có","Không")) | R27: Performance
A28: K24 | B28: Hiệu năng | C28: Kích thước model | D28: KB | E28: Thấp | F28: =IF(Performance!C60="","",Performance!C60) | G28: =IF(Performance!F60="","",Performance!F60) | H28: =IF(OR(F28="",G28=""),"",G28-F28) | I28: =IF(OR(F28="",G28=""),"",IFERROR((G28-F28)/ABS(F28),"")) | K28: 0 | L28: =IF(OR(G28="",J28=""),"",IF(E28="Thấp",IF(G28<=J28,"Có","Không"),IF(G28>=J28,"Có","Không"))) | M28: =IF(OR(F28="",G28="",K28=""),"",IF(E28="Thấp",IF(G28<=F28+K28,"Có","Không"),IF(G28>=F28-K28,"Có","Không"))) | N28: =IF(G28="","Chưa đo",IF(OR(L28="Không",M28="Không"),"Không đạt",IF(AND(L28="",M28=""),"Chưa có tiêu chí","Đạt"))) | Q28: =IF(OR(O28="",P28=""),"",IF(OR(O28>0,P28<0),"Có","Không")) | R28: Performance
A29: K25 | B29: Hiệu năng | C29: Thời gian init | D29: ms | E29: Thấp | F29: =IF(Performance!C40="","",Performance!C40) | G29: =IF(Performance!F40="","",Performance!F40) | H29: =IF(OR(F29="",G29=""),"",G29-F29) | I29: =IF(OR(F29="",G29=""),"",IFERROR((G29-F29)/ABS(F29),"")) | K29: 10 | L29: =IF(OR(G29="",J29=""),"",IF(E29="Thấp",IF(G29<=J29,"Có","Không"),IF(G29>=J29,"Có","Không"))) | M29: =IF(OR(F29="",G29="",K29=""),"",IF(E29="Thấp",IF(G29<=F29+K29,"Có","Không"),IF(G29>=F29-K29,"Có","Không"))) | N29: =IF(G29="","Chưa đo",IF(OR(L29="Không",M29="Không"),"Không đạt",IF(AND(L29="",M29=""),"Chưa có tiêu chí","Đạt"))) | Q29: =IF(OR(O29="",P29=""),"",IF(OR(O29>0,P29<0),"Có","Không")) | R29: Performance
C31: Tổng hợp gate
C32: Đạt | D32: =COUNTIF($N$5:$N$29,"Đạt")
C33: Không đạt | D33: =COUNTIF($N$5:$N$29,"Không đạt")
C34: Chưa đo | D34: =COUNTIF($N$5:$N$29,"Chưa đo")
C35: Chưa có tiêu chí | D35: =COUNTIF($N$5:$N$29,"Chưa có tiêu chí")
C36: Kết luận chung | D36: =IF(D33>0,"KHÔNG ĐẠT",IF(D34+D35>0,"CHƯA ĐỦ DỮ LIỆU","ĐẠT"))
A38: CI Δ = khoảng tin cậy 95% của (candidate − baseline) từ paired bootstrap theo file. "Có ý nghĩa" khi khoảng không chứa 0.

Sheet Snapshot
A1: Snapshot baseline – cấu hình được đóng băng
A2: Mọi số liệu baseline phải truy được về đúng cấu hình này. Cột vàng = bạn điền; cột 'Thay đổi?' tự đánh dấu mục candidate khác baseline.
A4: Nhóm | B4: Hạng mục | C4: Baseline | D4: Candidate | E4: Thay đổi? | F4: Ghi chú
A5: Chung | B5: Tên phiên bản / git tag | E5: =IF(D5="","",IF(D5=C5,"","Đổi"))
A6: Chung | B6: Ngày chốt | E6: =IF(D6="","",IF(D6=C6,"","Đổi")) | F6: Định dạng dd/mm/yyyy
A7: Chung | B7: Người chốt | E7: =IF(D7="","",IF(D7=C7,"","Đổi"))
A8: Model | B8: File model | E8: =IF(D8="","",IF(D8=C8,"","Đổi"))
A9: Model | B9: SHA256 file model | E9: =IF(D9="","",IF(D9=C9,"","Đổi")) | F9: sha256sum <model>
A10: Model | B10: Kiến trúc | C10: YAMNet transfer learning, 2 lớp | E10: =IF(D10="","",IF(D10=C10,"","Đổi")) | F10: Theo cấu hình hiện tại
A11: Model | B11: Kiểu số (float32 / fp16 / int8) | E11: =IF(D11="","",IF(D11=C11,"","Đổi"))
A12: Lib | B12: Commit lib.so | E12: =IF(D12="","",IF(D12=C12,"","Đổi"))
A13: Lib | B13: Compiler & build flags | E13: =IF(D13="","",IF(D13=C13,"","Đổi")) | F13: vd clang, -O3, LTO, strip
A14: Lib | B14: Runtime & version (TFLite / ONNX, delegate) | E14: =IF(D14="","",IF(D14=C14,"","Đổi"))
A15: Input lib | B15: Input PCM chấp nhận (sample rate, số kênh, kiểu mẫu) | E15: =IF(D15="","",IF(D15=C15,"","Đổi")) | F15: Hợp đồng giữa app và lib; decode nằm ngoài lib
A16: Input lib | B16: Độ dài input tối đa | E16: =IF(D16="","",IF(D16=C16,"","Đổi")) | F16: Giới hạn theo RAM, xem File dai va batch
A17: Tiền xử lý | B17: Resampler (thư viện, chất lượng) | E17: =IF(D17="","",IF(D17=C17,"","Đổi")) | F17: Phải khớp tiền xử lý lúc train
A18: Tiền xử lý | B18: Cách downmix | E18: =IF(D18="","",IF(D18=C18,"","Đổi")) | F18: vd trung bình các kênh / lấy kênh 0
A19: Tham số | B19: Sample rate model (Hz) | C19: 16000 | E19: =IF(D19="","",IF(D19=C19,"","Đổi")) | F19: Theo checklist mục 5c
A20: Tham số | B20: Window (s) | C20: 0.96 | E20: =IF(D20="","",IF(D20=C20,"","Đổi")) | F20: YAMNet
A21: Tham số | B21: Hop (s) | C21: 0.08 | E21: =IF(D21="","",IF(D21=C21,"","Đổi"))
A22: Tham số | B22: Xử lý cửa sổ cuối (< 0.96 s) | C22: Bỏ phần dư (chỉ cửa sổ đủ 15 600 mẫu) | E22: =IF(D22="","",IF(D22=C22,"","Đổi")) | F22: Pad 0 / bỏ / cửa sổ lùi về cuối file
A23: Tham số | B23: Cách gộp score overlap | C23: trọng số tam giác theo tâm cửa sổ + làm mượt trung bình 5 hop | E23: =IF(D23="","",IF(D23=C23,"","Đổi")) | F23: Mean / max / median / trọng số – xem Ablation mục B
A24: Tham số | B24: Ngưỡng quyết định | C24: ='KQ du lieu that'!$B$11 | E24: =IF(D24="","",IF(D24=C24,"","Đổi")) | F24: Youden trên dữ liệu thiết kế – thay bằng ngưỡng chọn trên dev (Bước 5)
A25: Tham số | B25: Pad trước (ms) | C25: 100 | E25: =IF(D25="","",IF(D25=C25,"","Đổi")) | F25: Cấu hình A4
A26: Tham số | B26: Pad sau (ms) | C26: 120 | E26: =IF(D26="","",IF(D26=C26,"","Đổi")) | F26: Cấu hình A4
A27: Tham số | B27: Drop: độ dài segment tối thiểu (ms) | C27: 0 | E27: =IF(D27="","",IF(D27=C27,"","Đổi")) | F27: Xem Ablation mục C
A28: Tham số | B28: Merge gap (ms) | C28: 500 | E28: =IF(D28="","",IF(D28=C28,"","Đổi")) | F28: Cấu hình A4
A29: Tham số | B29: Thứ tự hậu xử lý | C29: padding → drop → merge | E29: =IF(D29="","",IF(D29=C29,"","Đổi")) | F29: Theo mô tả pipeline – kiểm tra lại; xem Ablation mục D
A30: Tham số | B30: Rebin để so GT (s) | C30: 0.5 | E30: =IF(D30="","",IF(D30=C30,"","Đổi"))
A31: Dữ liệu | B31: Version tập dev | C31: Nhãn trong C:/Users/leuhu/OneDrive/Máy tính/test/data/AAA/Ground_truth; chia theo file, phân tầng category, seed 3 | E31: =IF(D31="","",IF(D31=C31,"","Đổi"))
A32: Dữ liệu | B32: Version tập test | C32: Nhãn trong C:/Users/leuhu/OneDrive/Máy tính/test/data/AAA/Ground_truth; chia theo file, phân tầng category, seed 3 | E32: =IF(D32="","",IF(D32=C32,"","Đổi"))
A33: Dữ liệu | B33: Số file dev / test | C33: =COUNTIFS('DL theo file'!$C$5:$C$148,"dev")&" / "&COUNTIFS('DL theo file'!$C$5:$C$148,"test") | E33: =IF(D33="","",IF(D33=C33,"","Đổi"))
A34: Dữ liệu | B34: Tổng giờ audio test | C34: =SUMIFS('DL theo file'!$D$5:$D$148,'DL theo file'!$C$5:$C$148,"test")/3600 | E34: =IF(D34="","",IF(D34=C34,"","Đổi"))
A35: Dữ liệu | B35: Version tập nhãn mịn (10–20 ms) | E35: =IF(D35="","",IF(D35=C35,"","Đổi")) | F35: Dùng cho sheet Bien va timestamp
A36: Dữ liệu | B36: Version tập non-speech dài | E36: =IF(D36="","",IF(D36=C36,"","Đổi")) | F36: Dùng cho sheet File dai va batch
A37: Đánh giá | B37: Commit script đánh giá | C37: evaluate_real.py + make_excel_real.py (vad_demo) | E37: =IF(D37="","",IF(D37=C37,"","Đổi"))
A38: Đánh giá | B38: Bootstrap: seed / số lần lặp | C38: 0 / 1000 | E38: =IF(D38="","",IF(D38=C38,"","Đổi")) | F38: vd 42 / 1000
A39: Đánh giá | B39: Thiết bị đo hiệu năng | E39: =IF(D39="","",IF(D39=C39,"","Đổi")) | F39: Chi tiết ở sheet Performance, mục A
A40: Tích hợp | B40: Decoder phía app & version | E40: =IF(D40="","",IF(D40=C40,"","Đổi")) | F40: ffmpeg / MediaCodec / AVFoundation / minimp3…
A41: Tích hợp | B41: Có bù encoder delay / priming (gapless) không | E41: =IF(D41="","",IF(D41=C41,"","Đổi")) | F41: Xem Tich hop decode mục B

Sheet Quy trinh 8 buoc
A1: Quy trình đánh giá VAD (bin 0.5s, có hậu xử lý)
A2: Cột vàng = bạn điền. Trạng thái chọn từ danh sách.
A4: Bước | B4: Tên bước | C4: Mục tiêu | D4: Việc cần làm | E4: Đầu ra | F4: Công cụ | G4: Trạng thái | H4: Ghi chú
A5: 1 | B5: Chia dữ liệu | C5: Tránh rò rỉ, đánh giá trung thực | D5: Chia dev ~30% / test ~70% theo nguồn gốc bản ghi (không theo clip); phân tầng theo category; bổ sung tập thật/khó (tự thu hoặc AVA-Speech). | E5: Danh sách file dev/test + cột group | F5: sklearn StratifiedGroupKFold, GroupShuffleSplit | G5: Đạt | H5: Dev 43 / test 101 file, chia theo file, phân tầng category (seed 3). Không có metadata nguồn để chia theo nhóm.
A6: 2 | B6: Chuẩn hóa GT | C6: Nhãn bin 0.5s rõ ràng, có cờ biên | D6: Tính frac_speech mỗi bin; gắn cờ bin biên (±1 bin) và bin mơ hồ; quy tắc rebin model trùng quy tắc tạo GT; gắn metadata (category, SNR, loại nền, loại giọng). | E6: Bảng bin: file, bin, y, frac, is_boundary, is_ambiguous, metadata | F6: numpy, pandas | G6: Đạt | H6: Bin 0.5 s từ nhãn chính; cờ biên ±1 bin.
A7: 3 | B7: Kiểm tra alignment & rò rỉ | C7: Loại lỗi pipeline trước khi đo | D7: Chạy sheet 'Kiem tra du lieu' (mục 5a–5e, 2a–2c): ghép file, thời lượng, 16 kHz mono, offset +0.48s, quét shift ±1s. | E7: Bảng cờ theo file; đồ thị F1 theo shift | F7: vadqc.py, soundfile, librosa | G7: Đang làm | H7: Alignment 5a–5e xong. Rò rỉ 2a–2c chưa làm (thiếu metadata).
A8: 4 | B8: Tầng A – điểm thô | C8: Đo khả năng phân biệt nội tại | D8: ROC-AUC, PR-AUC, DET, TPR@FPR=1%/5%, reliability diagram; micro + macro theo file/category; trên 3 tập bin: tất cả / không biên / rõ ràng. | E8: Bảng metric tầng A + ROC/PR/DET | F8: sklearn.metrics | G8: Đạt | H8: KQ du lieu that mục F: AUC, PR-AUC, TPR@FPR bằng công thức; tất cả / không biên. Chưa vẽ reliability diagram.
A9: 5 | B9: Chọn ngưỡng trên dev | C9: Điểm vận hành phù hợp ứng dụng | D9: Quét ngưỡng qua TOÀN pipeline trên dev; tối thiểu DCF hoặc cố định FAR; ghi lại ngưỡng Youden tầng A để so sánh; bootstrap CI của ngưỡng. | E9: Ngưỡng cố định cho test + CI | F9: numpy, sklearn | G9: Đang làm | H9: KQ du lieu that mục A, E: ngưỡng chọn bằng công thức theo tiêu chí ở B8. Cần chốt tiêu chí (DCF hay FAR cố định).
A10: 6 | B10: Tầng B – đầu ra cuối (test) | C10: Đo hiệu năng người dùng cảm nhận | D10: MR, FAR, F1, DCF, DetER ở 3 chế độ (strict / ±1 bin / chỉ biên); tách FEC/MSC/OVER/NDS; event-F1 (t_collar=0.5s); fragmentation/over-merge; histogram Δonset/Δoffset. | E10: Sheet 'Bao cao category' + đồ thị | F10: pyannote.metrics, sed_eval | G10: Đạt | H10: KQ du lieu that mục B, C, I: MR/FAR/F1/DCF 3 chế độ, FEC/MSC/OVER/NDS, event-F1, Δbiên. Chưa tính DetER.
A11: 7 | B11: Ablation hậu xử lý | C11: Quy trách nhiệm lỗi model vs hậu xử lý | D11: Chạy A0–A4 và lưới quét pad/merge (sheet 'Ablation'); đếm riêng gap GT ≤1s bị lấp. | E11: Bảng ablation + heatmap F1(pad, merge) | F11: script nội bộ | G11: Đạt | H11: KQ du lieu that mục D + heatmap DCF (Hinh du lieu that, hình 3).
A12: 8 | B12: Báo cáo | C12: Kết quả có CI, phân tầng, có giải thích | D12: Mỗi metric kèm CI 95% bootstrap theo file; bảng per-category; top-K file lỗi đã nghe kiểm tra kèm nguyên nhân; báo cả số tổng hợp và số dữ liệu thật. | E12: Báo cáo cuối | F12: matplotlib | G12: Đang làm | H12: Có CI + per-category. Chưa nghe kiểm tra top-K (mục J).
A14: Tiến độ | B14: =COUNTIF(G5:G12,"Đạt")/(COUNTA(G5:G12)-COUNTIF(G5:G12,"Không áp dụng")) | C14: Tỷ lệ = số bước 'Đạt' / số bước áp dụng

Sheet Metrics
A1: Danh mục metric
A2: Tầng A = điểm thô trước hậu xử lý; Tầng B = đầu ra nhị phân sau hậu xử lý. Tầng C = hiệu năng lib; tầng S = biên, file, parity; tầng I = tích hợp decode (ngoài lib).
A4: Tầng | B4: Metric | C4: Định nghĩa / công thức | D4: Ý nghĩa | E4: Công cụ | F4: Chế độ báo cáo
A5: A | B5: ROC-AUC | C5: Diện tích dưới đường ROC | D5: Khả năng xếp hạng speech > non-speech | E5: roc_auc_score | F5: micro + macro; tất cả / không biên / rõ ràng
A6: A | B6: PR-AUC (AP) | C6: Diện tích dưới đường Precision-Recall | D6: Phản ánh đúng hơn khi mất cân bằng lớp | E6: average_precision_score | F6: micro + macro
A7: A | B7: DET curve | C7: FNR vs FPR trên trục normal deviate | D7: Chuẩn ngành speech, rõ vùng FAR thấp | E7: det_curve, DetCurveDisplay | F7: micro
A8: A | B8: TPR @ FPR cố định | C8: TPR khi FPR = 1% / 5% | D8: Điểm vận hành thực tế | E8: roc_curve | F8: micro
A9: A | B9: Calibration (ECE, Brier) | C9: Reliability diagram; Brier = mean((p−y)²) | D9: Score có dùng như xác suất được không | E9: calibration_curve, brier_score_loss | F9: micro
A10: B | B10: Miss rate (MR) | C10: FN / tổng bin speech GT | D10: Bỏ sót speech | E10: tự tính / pyannote | F10: strict / ±1 bin / chỉ biên
A11: B | B11: False alarm rate (FAR) | C11: FP / tổng bin non-speech GT | D11: Báo nhầm speech | E11: tự tính / pyannote | F11: strict / ±1 bin / chỉ biên
A12: B | B12: Precision / Recall / F1 | C12: Theo bin, lớp speech | D12: Chất lượng tổng thể | E12: sklearn | F12: strict / ±1 bin
A13: B | B13: Specificity, Balanced acc. | C13: TN/(TN+FP); (TPR+TNR)/2 | D13: Ít phụ thuộc tỉ lệ lớp | E13: sklearn | F13: strict / ±1 bin
A14: B | B14: Detection Error Rate | C14: (FA + Miss) / tổng speech | D14: Chuẩn pyannote | E14: pyannote DetectionErrorRate(collar=1.0) | F14: strict / collar
A15: B | B15: DCF | C15: 0.75·MR + 0.25·FAR | D15: Chuẩn NIST OpenSAT, phạt miss nặng hơn | E15: pyannote DetectionCostFunction | F15: strict / ±1 bin
... A31: I | B31: Lệch timestamp decode | C31: Lag cross-correlation giữa PCM decode và wav gốc | D31: Encoder delay / priming làm lệch mọi segment | E31: script, ffmpeg | F31: ms theo định dạng

Sheet Kiem tra du lieu
A1: Checklist kiểm tra chất lượng dữ liệu (Bước 8)
A2: Thứ tự khuyến nghị: 5 → 1 → 2 → 3 → 4. Ngưỡng là ngưỡng thực hành, hãy tự hiệu chỉnh. Cột vàng = bạn điền.
A4: Mã | B4: Nhóm | C4: Kiểm tra | D4: Cách đo | E4: Ngưỡng cảnh báo | F4: Hành động khi bị gắn cờ | G4: Kết quả đo | H4: Trạng thái | I4: Ghi chú
A5: 5a | B5: Căn chỉnh | C5: Ghép file Model↔GT | D5: pair_files: thiếu, dư, sai category | E5: Bất kỳ lỗi nào | F5: Sửa tên/đường dẫn trước mọi bước khác | G5: 144 file ghép đủ output model ↔ nhãn ↔ audio; 0 vấn đề | H5: Đạt
A6: 5b | B6: Căn chỉnh | C6: Thời lượng / số bin | D6: wav_dur vs n_bins×0.5; last_end của model | E6: Lệch > 1 bin | F6: Kiểm tra cắt clip, padding cuối file | G6: 0 file lệch số bin / số cửa sổ / thời lượng | H6: Đạt | I6: n_bins = floor(thời lượng / 0.5)
A7: 5c | B7: Căn chỉnh | C7: Định dạng audio | D7: sr = 16000, mono, biên độ [-1,1] | E7: Khác | F7: Resample (librosa), chạy lại YAMNet | G7: 144/144 file 16 kHz mono | H7: Đạt
A8: 5d | B8: Căn chỉnh | C8: Hop / cửa sổ | D8: diff(start) = 0.08; end − start = 0.96 | E8: Sai | F8: Sửa script xuất file | G8: hop sai 0, cửa sổ sai 0, score ngoài [0,1] 0 | H8: Đạt
A9: 5e | B9: Căn chỉnh | C9: Offset tâm cửa sổ | D9: Quét shift ±1s, bước 0.08s; cross-correlation theo file | E9: Đỉnh F1 lệch 0 quá ±0.08s | F9: Cộng +0.48s; đánh giá lại | G9: Đỉnh F1 (thr 0.5) +80 ms trên nhãn chính; đỉnh AUC trên nhãn chính xác (val tổng hợp) +0 ms | H9: Đạt | I9: Dùng val tổng hợp (nhãn chính xác) làm mốc; AUC trên nhãn chính tăng 0.0010 nếu dịch; 46 file |lag| ≥ 0.4 s (xem tương quan đỉnh).
A10: 1a | B10: Phân bố | C10: File suy biến | D10: Tỉ lệ speech = 0 hoặc 1 | E10: > 5–10% số file | F10: Loại khỏi chỉ số per-file; báo riêng | G10: ='KQ du lieu that'!$B$75&"/"&'KQ du lieu that'!$B$73&" file ("&FIXED('KQ du lieu that'!$B$76*100,1)&"%) chỉ có 1 lớp" | H10: =IF('KQ du lieu that'!$B$76>0.1,"Không đạt","Đạt") | I10: Loại khỏi AUC theo file; giữ trong chỉ số gộp. Quy tắc: > 10% -> Không đạt.
A11: 1b | B11: Phân bố | C11: File cực đoan | D11: Tỉ lệ speech < 0.1 hoặc > 0.9 | E11: > 30% số file | F11: Cân bằng lại khi sinh dữ liệu | G11: =FIXED('KQ du lieu that'!$B$77*100,1)&"% file có tỉ lệ speech < 0.1 hoặc > 0.9" | H11: =IF('KQ du lieu that'!$B$77>0.3,"Không đạt","Đạt")
A12: 1c | B12: Phân bố | C12: Độ phức tạp thời gian | D12: #transitions, độ dài đoạn, % bin biên | E12: Trung vị transitions ≤ 1 | F12: Thêm clip nhiều chuyển trạng thái | G12: ="Trung vị "&FIXED('KQ du lieu that'!$B$78,1)&" lần chuyển trạng thái / file" | H12: =IF('KQ du lieu that'!$B$78<=1,"Không đạt","Đạt")
A13: 1d | B13: Phân bố | C13: AUC pooled vs theo file | D13: Chênh lệch; AUC file tệ nhất | E13: Chênh > 0.005; file < 0.9 | F13: Xem timeline các file tệ | G13: ="AUC gộp "&FIXED('KQ du lieu that'!$B$79,3)&" vs macro theo file "&FIXED('KQ du lieu that'!$B$80,3)&"; "&'KQ du lieu that'!$B$83&" file < 0.9, tệ nhất "&FIXED('KQ du lieu that'!$B$85,3)&" ("&'KQ du lieu that'!$B$86&")" | H13: =IF(OR(ABS('KQ du lieu that'!$B$82)>0.005,'KQ du lieu that'!$B$83>0),"Không đạt","Đạt") | I13: Xem Hinh du lieu that, hình 1 và 4.
A14: 2a | B14: Rò rỉ | C14: Rò rỉ theo metadata | D14: Union-find trên speech_src/noise_src/speaker; #nhóm vắt qua 2 phía | E14: > 0 | F14: Chia lại bằng StratifiedGroupKFold | G14: Chưa có metadata nguồn / người nói; dev/test chia theo file, phân tầng category | H14: Chưa làm
A15: 2b | B15: Rò rỉ | C15: Trùng / gần trùng | D15: MD5, Chromaprint, cosine embedding YAMNet | E15: Vượt τ đã hiệu chỉnh | F15: Gộp nhóm hoặc bỏ khỏi test | H15: Chưa làm
A16: 2c | B16: Rò rỉ | C16: Tác động của rò rỉ | D16: AUC nhóm 'đã thấy' vs 'mới'; retrain theo nhóm | E16: ΔAUC ≥ 0.01 | F16: Báo con số sau khi chia theo nhóm | G16: Cần danh sách nguồn dữ liệu train để đối chiếu | H16: Chưa làm
A17: 3a | B17: Nhãn | C17: Đồng thuận nhãn | D17: Cohen/Fleiss κ (biên vs trong), PABAK, lệch biên (ms) | E17: κ trong < 0.9; median lệch > 250ms | F17: Viết lại hướng dẫn, gán nhãn lại | G17: Không có người gán nhãn thứ 2 | H17: Chưa làm | I17: Thêm --label2 (nhãn người gán 2) khi chạy evaluate_real.py
A18: 3b | B18: Nhãn | C18: Nhãn đáng ngờ | D18: cleanlab (out-of-fold) + quy tắc tự tin | E18: — | F18: Nghe lại 30–50 bin đầu danh sách | G18: 994 đoạn / 2843 bin điểm trái ngược mạnh với nhãn | H18: Đang làm | I18: KQ du lieu that mục J; đủ danh sách: results_test/suspicious.csv
A19: 4a | B19: Độ khó | C19: Độ tách điểm số | D19: % bin 0.1<p<0.9; đường F1 theo ngưỡng | E19: < 2% và F1 phẳng | F19: Thêm hard negative / SNR thấp | G19: 23.9% bin có 0.1<p<0.9; F1 thay đổi 0.011 trong ngưỡng 0.2–0.9 | H19: Đạt
A20: 4b | B20: Độ khó | C20: Hard negative | D20: Số giây theo loại non-speech | E20: Không có nhạc có lời/TV/cười | F20: Bổ sung (vd. MUSAN có vocal) | G20: Category: Asm, Babble, Clean, Music, Noise | H20: Đang làm | I20: Kiểm tra thủ công có đủ nền khó: nhạc có lời, đám đông, TV, tiếng cười
A21: 4c | B21: Độ khó | C21: Phân bố SNR | D21: Histogram SNR; AUC theo bucket | E21: > 80% ở trên 15 dB | F21: Sinh thêm dữ liệu 0–10 dB | G21: Không có metadata SNR | H21: Chưa làm
A22: 4d | B22: Độ khó | C22: Kiểm chứng thực tế | D22: Đánh giá trên bộ test thật | E22: Chênh lớn so với dữ liệu tổng hợp | F22: Báo cả hai; ưu tiên số thực | G22: ="AUC val tổng hợp "&FIXED('KQ du lieu that'!$B$68,3)&" vs test "&FIXED('KQ du lieu that'!$D$59,3) | H22: Đạt | I22: Báo cả hai; ưu tiên số thật
B24: Tổng hợp
B25: Đạt | C25: =COUNTIF($H$5:$H$22,B25)
B26: Không đạt | C26: =COUNTIF($H$5:$H$22,B26)
B27: Đang làm | C27: =COUNTIF($H$5:$H$22,B27)
B28: Chưa làm | C28: =COUNTIF($H$5:$H$22,B28)
B29: Không áp dụng | C29: =COUNTIF($H$5:$H$22,B29)
B30: % hoàn thành | C30: =IFERROR((C25+C26)/(COUNTA(H5:H22)-C29),0)

Sheet Ablation
A1: Ablation hậu xử lý
A2: Điền MR, FAR, F1 (dạng thập phân, vd 0.05 = 5%). DCF và Δ được tính tự động. Hàng xám = ví dụ minh họa, hãy ghi đè.
A4: Cấu hình | B4: Rescore | C4: Pad trước (ms) | D4: Pad sau (ms) | E4: Merge gap (ms) | F4: Rebin | G4: MR | H4: FAR | I4: F1 strict | J4: F1 ±1 bin | K4: DCF | L4: ΔDCF so với A0 | M4: Ghi chú
A5: A0 – thô | B5: – | C5: 0 | D5: 0 | E5: 0 | F5: midpoint → bin | G5: ='KQ du lieu that'!P42 | H5: ='KQ du lieu that'!Q42 | I5: ='KQ du lieu that'!R42 | J5: ='KQ du lieu that'!S42 | K5: =0.75*G5+0.25*H5 | L5: =K5-$K$5 | M5: ="Ngưỡng "&'KQ du lieu that'!$B$8&" trên dev = "&FIXED('KQ du lieu that'!C42,2)
A6: A1 | B6: ✓ | C6: 0 | D6: 0 | E6: 0 | F6: ✓ | G6: ='KQ du lieu that'!P43 | H6: ='KQ du lieu that'!Q43 | I6: ='KQ du lieu that'!R43 | J6: ='KQ du lieu that'!S43 | K6: =0.75*G6+0.25*H6 | L6: =K6-$K$5 | M6: ="Ngưỡng "&'KQ du lieu that'!$B$8&" trên dev = "&FIXED('KQ du lieu that'!C43,2)
A7: A2 | B7: ✓ | C7: 100 | D7: 120 | E7: 0 | F7: ✓ | G7: ='KQ du lieu that'!P44 | H7: ='KQ du lieu that'!Q44 | I7: ='KQ du lieu that'!R44 | J7: ='KQ du lieu that'!S44 | K7: =0.75*G7+0.25*H7 | L7: =K7-$K$5 | M7: ="Ngưỡng "&'KQ du lieu that'!$B$8&" trên dev = "&FIXED('KQ du lieu that'!C44,2)
A8: A3 | B8: ✓ | C8: 0 | D8: 0 | E8: 500 | F8: ✓ | G8: ='KQ du lieu that'!P45 | H8: ='KQ du lieu that'!Q45 | I8: ='KQ du lieu that'!R45 | J8: ='KQ du lieu that'!S45 | K8: =0.75*G8+0.25*H8 | L8: =K8-$K$5 | M8: ="Ngưỡng "&'KQ du lieu that'!$B$8&" trên dev = "&FIXED('KQ du lieu that'!C45,2)
A9: A4 – hiện tại | B9: ✓ | C9: 100 | D9: 120 | E9: 500 | F9: ✓ | G9: ='KQ du lieu that'!P46 | H9: ='KQ du lieu that'!Q46 | I9: ='KQ du lieu that'!R46 | J9: ='KQ du lieu that'!S46 | K9: =0.75*G9+0.25*H9 | L9: =K9-$K$5 | M9: ="Ngưỡng "&'KQ du lieu that'!$B$8&" trên dev = "&FIXED('KQ du lieu that'!C46,2)
A11: Lưới quét đề xuất: pad trước {0, 50, 100, 200} ms × pad sau {0, 60, 120, 240} ms × merge gap {0, 250, 500, 750, 1000} ms × drop {0, 100, 250, 500} ms.
A12: Đọc kết quả: MSC/NDS cao từ A0 → lỗi model. FAR tăng từ A2→A4, tập trung ở offset → do pad/merge. Merge < 500ms dễ lấp khoảng lặng dài 1 bin.
A14: B. Cách gộp score overlap (hậu xử lý giữ như A4)
A15: Mã | B15: Cách gộp score cho mỗi hop | F15: Recall 1 s cuối file | G15: MR | H15: FAR | I15: F1 strict | J15: F1 ±1 bin | K15: DCF | L15: ΔDCF so với dòng đầu | M15: Ghi chú
A16: O0 | B16: Chỉ cửa sổ có tâm gần hop nhất (không gộp) | K16: =IF(OR(G16="",H16=""),"",0.75*G16+0.25*H16) | L16: =IF(OR(K16="",$K$16=""),"",K16-$K$16) | M16: Chưa đo
A17: O1 | B17: Mean các cửa sổ phủ hop | K17: =IF(OR(G17="",H17=""),"",0.75*G17+0.25*H17) | L17: =IF(OR(K17="",$K$16=""),"",K17-$K$16)
A18: O2 | B18: Max các cửa sổ phủ hop | K18: =IF(OR(G18="",H18=""),"",0.75*G18+0.25*H18) | L18: =IF(OR(K18="",$K$16=""),"",K18-$K$16)
A19: O3 | B19: Median các cửa sổ phủ hop | K19: =IF(OR(G19="",H19=""),"",0.75*G19+0.25*H19) | L19: =IF(OR(K19="",$K$16=""),"",K19-$K$16)
A20: O4 | B20: Trung bình trọng số theo khoảng cách tới tâm cửa sổ | G20: ='KQ du lieu that'!P46 | H20: ='KQ du lieu that'!Q46 | I20: ='KQ du lieu that'!R46 | J20: ='KQ du lieu that'!S46 | K20: =IF(OR(G20="",H20=""),"",0.75*G20+0.25*H20) | L20: =IF(OR(K20="",$K$16=""),"",K20-$K$16) | M20: Giống A4 (trọng số tam giác theo tâm cửa sổ + làm mượt trung bình 5 hop)
A22: C. Drop – độ dài segment tối thiểu (pad / merge giữ như A4)
A23: Mã | B23: Pad trước (ms) | C23: Pad sau (ms) | D23: Merge gap (ms) | E23: Drop (ms) | F23: #segment dự đoán / #GT | G23: MR | H23: FAR | I23: F1 strict | J23: F1 ±1 bin | K23: DCF | L23: ΔDCF so với dòng đầu | M23: Ghi chú
A24: C0 | B24: 100 | C24: 120 | D24: 500 | E24: 0 | F24: 1.2059202 | G24: ='KQ du lieu that'!P46 | H24: ='KQ du lieu that'!Q46 | I24: ='KQ du lieu that'!R46 | J24: ='KQ du lieu that'!S46 | K24: =IF(OR(G24="",H24=""),"",0.75*G24+0.25*H24) | L24: =IF(OR(K24="",$K$24=""),"",K24-$K$24) | M24: Giống A4 (không drop)
A25: C1 | B25: 100 | C25: 120 | D25: 500 | E25: 100 | K25: =IF(OR(G25="",H25=""),"",0.75*G25+0.25*H25) | L25: =IF(OR(K25="",$K$24=""),"",K25-$K$24)
A26: C2 | B26: 100 | C26: 120 | D26: 500 | E26: 250 | K26: =IF(OR(G26="",H26=""),"",0.75*G26+0.25*H26) | L26: =IF(OR(K26="",$K$24=""),"",K26-$K$24)
A27: C3 | B27: 100 | C27: 120 | D27: 500 | E27: 500 | K27: =IF(OR(G27="",H27=""),"",0.75*G27+0.25*H27) | L27: =IF(OR(K27="",$K$24=""),"",K27-$K$24)
A28: C4 | B28: 100 | C28: 120 | D28: 500 | E28: 750 | K28: =IF(OR(G28="",H28=""),"",0.75*G28+0.25*H28) | L28: =IF(OR(K28="",$K$24=""),"",K28-$K$24)
A30: D. Thứ tự hậu xử lý (tham số giữ như A4 + drop đã chọn)
A31: Mã | B31: Thứ tự | F31: #segment dự đoán / #GT | G31: MR | H31: FAR | I31: F1 strict | J31: F1 ±1 bin | K31: DCF | L31: ΔDCF so với dòng đầu | M31: Ghi chú
A32: P1 | B32: padding → drop → merge (hiện tại) | F32: 1.2059202 | G32: ='KQ du lieu that'!P46 | H32: ='KQ du lieu that'!Q46 | I32: ='KQ du lieu that'!R46 | J32: ='KQ du lieu that'!S46 | K32: =IF(OR(G32="",H32=""),"",0.75*G32+0.25*H32) | L32: =IF(OR(K32="",$K$32=""),"",K32-$K$32) | M32: Giống A4: padding → merge, drop = 0
A33: P2 | B33: padding → merge → drop | K33: =IF(OR(G33="",H33=""),"",0.75*G33+0.25*H33) | L33: =IF(OR(K33="",$K$32=""),"",K33-$K$32)
A34: P3 | B34: merge → drop → padding | K34: =IF(OR(G34="",H34=""),"",0.75*G34+0.25*H34) | L34: =IF(OR(K34="",$K$32=""),"",K34-$K$32)
A35: P4 | B35: drop → merge → padding | K35: =IF(OR(G35="",H35=""),"",0.75*G35+0.25*H35) | L35: =IF(OR(K35="",$K$32=""),"",K35-$K$32)
A36: Chọn xong cách gộp, drop và thứ tự thì ghi vào Snapshot. #segment dự đoán / #GT > 1 = phân mảnh; < 1 = gộp quá tay.

Sheet Bao cao category
A1: Báo cáo theo category (tầng B, trên test)
A2: Điền số liệu theo category. DCF, lỗi biên tính tự động. Hàng xám = ví dụ minh họa.
